<robot name="plane">
<link name="cylinder">
  <visual>
    <geometry>
      <cylinder radius="0.2" length="0.05"/>
    </geometry>
  </visual>
  <collision>
    <geometry>
      <cylinder radius="0.2" length="0.05"/>
    </geometry>
  </collision>
  <inertial>
    <mass value="1"/>
    <inertia ixx="0"  ixy="0"  ixz="0" iyy="0" iyz="0" izz="0" />
  </inertial>
</link>
<link name="box">
  <visual>
    <geometry>
      <cylinder radius="0.2" length="0.05"/>
    </geometry>
  </visual>
  <collision>
    <geometry>
      <cylinder radius="0.2" length="0.05"/>
    </geometry>
  </collision>
  <inertial>
    <mass value="1"/>
    <inertia ixx="0"  ixy="0"  ixz="0" iyy="0" iyz="0" izz="0" />
  </inertial>
</link>
<joint name = "world_to_box" type="continuous">
        <parent link="cylinder"/>
        <child link="box"/>
        <origin xyz="0 0 3" rpy="0 1.5707 0"/>
        <limit effort="0" velocity="0"/>
        <dynamics damping="1" friction="0"/>
        <axis xyz="0 0 1"/>
</joint>
</robot>